<?xml version="1.0"?>
<!-- This URDF was automatically created by SolidWorks to URDF Exporter! Originally created by Stephen Brawner (brawner@gmail.com) -->
<robot name="rover_21_description">

  <!-- Dummy root link -->
  <link name="dummy_root">
  </link>

  <!-- Fixed joint between dummy root and base_link -->
  <joint name="dummy_root_to_base_joint" type="fixed">
    <parent link="dummy_root"/>
    <child link="base_link"/>
    <origin xyz="0 0 0" rpy="0 0 0"/>
  </joint>

  <!-- Base Link -->
  <link name="base_link">
    <inertial>
      <origin xyz="-0.0597176388871317 -2.21514952908342E-09 0.0432014783103323" rpy="0 0 0"/>
      <mass value="7.6451763291456"/>
      <inertia ixx="0.168439329083486" ixy="-1.08629887891622E-05" ixz="0.0407415251600241"
               iyy="0.481545696094267" iyz="5.75369711790317E-08" izz="0.541121238422161"/>
    </inertial>
    <visual>
      <origin xyz="0 0 0" rpy="0 0 0"/>
      <geometry>
        <mesh filename="/home/svab/ros2_ws/src/ros2_rover/rover/meshes/base_link.STL"/>
      </geometry>
      <material name="">
        <color rgba="0.792156862745098 0.819607843137255 0.933333333333333 1"/>
      </material>
    </visual>
    <collision>
      <origin xyz="0 0 0" rpy="0 0 0"/>
      <geometry>
        <mesh filename="/home/svab/ros2_ws/src/ros2_rover/rover/meshes/base_link.STL"/>
      </geometry>
    </collision>
  </link>

  <!-- Left Front Link -->
  <link name="left_front_link">
    <inertial>
      <origin xyz="-0.0755097276903981 0.000138247434987249 -4.79303458726932E-05" rpy="0 0 0"/>
      <mass value="1.15731252096219"/>
      <inertia ixx="0.0178302511822237" ixy="-2.09274363582099E-06" ixz="1.4204407926078E-06"
               iyy="0.00968270185063617" iyz="1.80036299754407E-06" izz="0.00969344166305502"/>
    </inertial>
    <visual>
      <origin xyz="0 0 0" rpy="0 0 0"/>
      <geometry>
        <mesh filename="/home/svab/ros2_ws/src/ros2_rover/rover/meshes/left_front_link.STL"/>
      </geometry>
      <material name="">
        <color rgba="0.792156862745098 0.819607843137255 0.933333333333333 1"/>
      </material>
    </visual>
    <collision>
      <origin xyz="0 0 0" rpy="0 0 0"/>
      <geometry>
        <mesh filename="/home/svab/ros2_ws/src/ros2_rover/rover/meshes/left_front_link.STL"/>
      </geometry>
    </collision>
  </link>

  <!-- Left Front Joint -->
  <joint name="left_front_joint" type="continuous">
    <origin xyz="0.353294657130572 0.3625 -0.154224967578181" rpy="-2.0786047357804 0 -1.5707963267949"/>
    <parent link="base_link"/>
    <child link="left_front_link"/>
    <axis xyz="-1 0 0"/>
  </joint>

  <!-- Right Front Link -->
  <link name="right_front_link">
    <inertial>
      <origin xyz="-2.84518155616587E-05 0.00014352757758429 -0.0754466264782706" rpy="0 0 0"/>
      <mass value="1.15731252096219"/>
      <inertia ixx="0.00969372906416445" ixy="2.68465121779082E-07" ixz="-1.11897159373537E-06"
               iyy="0.00968241444952688" iyz="2.26828802029305E-06" izz="0.0178302511822238"/>
    </inertial>
    <visual>
      <origin xyz="0 0 0" rpy="0 0 0"/>
      <geometry>
        <mesh filename="/home/svab/ros2_ws/src/ros2_rover/rover/meshes/right_front_link.STL"/>
      </geometry>
      <material name="">
        <color rgba="0.792156862745098 0.819607843137255 0.933333333333333 1"/>
      </material>
    </visual>
    <collision>
      <origin xyz="0 0 0" rpy="0 0 0"/>
      <geometry>
        <mesh filename="/home/svab/ros2_ws/src/ros2_rover/rover/meshes/right_front_link.STL"/>
      </geometry>
    </collision>
  </link>

  <!-- Right Front Joint -->
  <joint name="right_front_joint" type="continuous">
    <origin xyz="0.353351994708173 -0.3625 -0.154125745497893" rpy="-1.5707963267949 0.966931818667219 0"/>
    <parent link="base_link"/>
    <child link="right_front_link"/>
    <axis xyz="0 0 1"/>
  </joint>

  <!-- Left Rear Link -->
  <link name="left_rear_link">
    <inertial>
      <origin xyz="-2.8451815541175E-05 0.000143527577594393 0.0755097276903982" rpy="0 0 0"/>
      <mass value="1.15731252096219"/>
      <inertia ixx="0.00969372906416443" ixy="2.6846512179334E-07" ixz="-1.11897159373079E-06"
               iyy="0.00968241444952685" iyz="2.26828802029616E-06" izz="0.0178302511822237"/>
    </inertial>
    <visual>
      <origin xyz="0 0 0" rpy="0 0 0"/>
      <geometry>
        <mesh filename="/home/svab/ros2_ws/src/ros2_rover/rover/meshes/left_rear_link.STL"/>
      </geometry>
      <material name="">
        <color rgba="0.792156862745098 0.819607843137255 0.933333333333333 1"/>
      </material>
    </visual>
    <collision>
      <origin xyz="0 0 0" rpy="0 0 0"/>
      <geometry>
        <mesh filename="/home/svab/ros2_ws/src/ros2_rover/rover/meshes/left_rear_link.STL"/>
      </geometry>
    </collision>
  </link>

  <!-- Left Rear Joint -->
  <joint name="left_rear_joint" type="continuous">
    <origin xyz="-0.355493804489844 0.3625 -0.150372421028072" rpy="1.5707963267949 1.53320191104535 3.14159265358979"/>
    <parent link="base_link"/>
    <child link="left_rear_link"/>
    <axis xyz="0 0 1"/>
  </joint>

  <!-- Right Rear Link -->
  <link name="right_rear_link">
    <inertial>
      <origin xyz="-2.84515837579713E-05 0.000143527620351219 -0.0754466264782706" rpy="0 0 0"/>
      <mass value="1.15731252096219"/>
      <inertia ixx="0.00969372911382251" ixy="2.68439980844609E-07" ixz="-1.11897159373792E-06"
               iyy="0.00968241439986873" iyz="2.26828802029381E-06" izz="0.0178302511822237"/>
    </inertial>
    <visual>
      <origin xyz="0 0 0" rpy="0 0 0"/>
      <geometry>
        <mesh filename="/home/svab/ros2_ws/src/ros2_rover/rover/meshes/right_rear_link.STL"/>
      </geometry>
      <material name="">
        <color rgba="0.792156862745098 0.819607843137255 0.933333333333333 1"/>
      </material>
    </visual>
    <collision>
      <origin xyz="0 0 0" rpy="0 0 0"/>
      <geometry>
        <mesh filename="/home/svab/ros2_ws/src/ros2_rover/rover/meshes/right_rear_link.STL"/>
      </geometry>
    </collision>
  </link>

  <!-- Right Rear Joint -->
  <joint name="right_rear_joint" type="continuous">
    <origin xyz="-0.353922288632598 -0.3625 -0.150480055091568" rpy="-1.5707963267949 0.867399709619945 0"/>
    <parent link="base_link"/>
    <child link="right_rear_link"/>
    <axis xyz="0 0 1"/>
  </joint>

  <!-- IMU Link and Joint -->
  <link name="imu_link">
    <visual>
      <origin xyz="0 0 0" rpy="0 0 0"/>
      <geometry>
        <box size="0.05 0.05 0.05"/>
      </geometry>
      <material name="">
        <color rgba="0.8 0.8 0.8 1"/>
      </material>
    </visual>
    <collision>
      <origin xyz="0 0 0" rpy="0 0 0"/>
      <geometry>
        <box size="0.05 0.05 0.05"/>
      </geometry>
    </collision>
    <inertial>
      <mass value="0.1"/>
      <inertia ixx="0.0001" ixy="0" ixz="0" iyy="0.0001" iyz="0" izz="0.0001"/>
    </inertial>
  </link>

  <joint name="base_to_imu_joint" type="fixed">
    <parent link="base_link"/>
    <child link="imu_link"/>
    <origin xyz="0 0 0" rpy="0 0 0"/>
  </joint>

  <!-- Camera Link and Joint -->
  <link name="camera_link">
    <visual>
      <origin xyz="0 0 0" rpy="0 0 0"/>
      <geometry>
        <box size="0.1 0.1 0.1"/>
      </geometry>
      <material name="">
        <color rgba="255 255 255 1"/>
      </material>
    </visual>
    <collision>
      <origin xyz="0 0 0" rpy="0 0 0"/>
      <geometry>
        <box size="0.1 0.1 0.1"/>
      </geometry>
    </collision>
    <inertial>
      <mass value="0.5"/>
      <inertia ixx="0.001" ixy="0" ixz="0" iyy="0.001" iyz="0" izz="0.001"/>
    </inertial>
  </link>

  <joint name="base_to_camera_joint" type="fixed">
    <parent link="base_link"/>
    <child link="camera_link"/>
    <origin xyz="0.2 0.0 0.172" rpy="0 0 0"/>
  </joint>

  <!-- Gazebo plugins and configurations -->
  <gazebo reference="imu_link">
    <gravity>true</gravity>
    <sensor name="imu_sensor" type="imu">
      <always_on>true</always_on>
      <update_rate>100</update_rate>
      <visualize>true</visualize>
      <plugin filename="libgazebo_ros_imu_sensor.so" name="imu_plugin">
        <topicName>imu</topicName>
        <ros>
        <namespace>/</namespace>
        <remapping>~/out:=/imu/data</remapping>
        <frame_name>imu_link</frame_name>
      </ros>
        <bodyName>imu_link</bodyName>
        <updateRateHZ>10.0</updateRateHZ>
        <xyzOffset>0 0 0</xyzOffset>
        <rpyOffset>0 0 0</rpyOffset>
        <frameName>imu_link</frameName>
        <initialOrientationAsReference>false</initialOrientationAsReference>
      </plugin>
      <pose>0 0 0 0 0 0</pose>
    </sensor>
  </gazebo>

  <gazebo reference="camera_link">
    <sensor name="camera_sensor" type="depth">
      <update_rate>30.0</update_rate>
      <camera>
        <horizontal_fov>1.047</horizontal_fov>
        <image>
          <width>640</width>
          <height>480</height>
          <format>R8G8B8</format>
        </image>
        <clip>
          <near>0.1</near>
          <far>100.0</far>
        </clip>
      </camera>
      <plugin name="camera_plugin" filename="libgazebo_ros_camera.so">
        <alwaysOn>true</alwaysOn>
        <updateRate>30.0</updateRate>
        <cameraName>camera</cameraName>
        <frameName>camera_link</frameName>
        <imageTopicName>image_raw</imageTopicName>
        <cameraInfoTopicName>camera_info</cameraInfoTopicName>
        <hackBaseline>0.07</hackBaseline>
        <distortionK1>0.0</distortionK1>
        <distortionK2>0.0</distortionK2>
        <distortionK3>0.0</distortionK3>
        <distortionT1>0.0</distortionT1>
        <distortionT2>0.0</distortionT2>
      </plugin>
    </sensor>
   
  </gazebo>
  <link name="gps_link">
    <visual>
      <geometry>
        <box size="0.02 0.02 0.02"/>
      </geometry>
      <material name="yellow">
        <color rgba="1 1 0 1"/>
      </material>
    </visual>
    <collision>
      <geometry>
        <box size="0.02 0.02 0.02"/>
      </geometry>
    </collision>
    <inertial>
      <mass value="0.01"/>
      <origin xyz="0 0 0"/>
      <inertia ixx="0.0001" ixy="0" ixz="0" iyy="0.0001" iyz="0" izz="0.0001"/>
    </inertial>
  </link>
  <joint name="gps_joint" type="fixed">
  <parent link="base_link"/>
  <child link="gps_link"/>
  <origin xyz="0 0 0.2" rpy="0 0 0"/> <!-- Adjust location as needed -->
 </joint>

<gazebo reference="gps_link">
  <sensor type="gps" name="gps">
  <always_on>true</always_on>
    <update_rate>10</update_rate>
    <plugin name="gps_plugin" filename="libgazebo_ros_gps_sensor.so">
      <ros>
        <namespace>/</namespace>
        <!--remapping>~/out:=/gps/fix</remapping-->
        <frame_name>gps_link</frame_name>
      </ros>
      <gps>
        <position_sensing>
          <horizontal>
            <noise type="gaussian">
              <mean>0</mean>
              <stddev>0.01</stddev>
            </noise>
          </horizontal>
          <vertical>
            <noise type="gaussian">
              <mean>0</mean>
              <stddev>0.01</stddev>
            </noise>
          </vertical>
        </position_sensing>
      </gps>
    </plugin>
  </sensor>
</gazebo>
  <gazebo>
    <plugin name="HAL_diff_drive_controller" filename="libgazebo_ros_diff_drive.so">
      <update_rate>50</update_rate>
      <num_wheel_pairs>2</num_wheel_pairs>
      <left_joint>left_front_joint</left_joint>
      <right_joint>right_front_joint</right_joint>
      <left_joint>left_rear_joint</left_joint>
      <right_joint>right_rear_joint</right_joint>
      <wheel_diameter>0.3</wheel_diameter>
      <wheel_separation>0.725</wheel_separation>
      <command_topic>cmd_vel</command_topic>
      <publish_odom>true</publish_odom>
      <publish_odom_tf>false</publish_odom_tf>
      <publish_wheel_tf>false</publish_wheel_tf>
      <odometry_topic>odom</odometry_topic>
      <odometry_frame>odom</odometry_frame>
              <ros>
        <namespace>/</namespace>
        <remapping>odom:=/odom/data</remapping>
        <frame_name>odom</frame_name>
      </ros>
      <robot_base_frame>base_footprint</robot_base_frame>
    </plugin>
  </gazebo>
</robot>
